{
 "cells": [
  {
   "cell_type": "code",
   "execution_count": null,
   "id": "df0fa411",
   "metadata": {},
   "outputs": [
    {
     "ename": "",
     "evalue": "",
     "output_type": "error",
     "traceback": [
      "\u001b[1;31mThe kernel failed to start as the Python Environment 'data_analysis (Python -1.-1.-1)' is no longer available. Consider selecting another kernel or refreshing the list of Python Environments."
     ]
    }
   ],
   "source": [
    "print(\"hello\")"
   ]
  },
  {
   "cell_type": "code",
   "execution_count": null,
   "id": "d92b2363",
   "metadata": {},
   "outputs": [],
   "source": []
  }
 ],
 "metadata": {
  "kernelspec": {
   "display_name": "data_analysis",
   "language": "python",
   "name": "python3"
  },
  "language_info": {
   "name": "python",
   "version": "undefined.undefined.undefined"
  }
 },
 "nbformat": 4,
 "nbformat_minor": 5
}
